Referenced by pull request #129640, Fix #129637: GPv3: Python: `add_points` raises exception
Referenced by commit 7e87da72ab4a68b2d1056107f84253a6a6e75cf1, Fix #129637: GPv3: Python: `add_points` raises exception
