Referenced by pull request #129640, Fix #129637: GPv3: Python: `add_points` raises exception
